Workbook

Sheet Rivers
A1: River ID | B1: River name | C1: Latitude | D1: Longitude | E1: Country | F1: Region | G1: Continent | H1: Ocean Basin | I1: Monthly discharge (Qm) (m3/s) | U1: interannual mean discharge (Qa=ΣQm / 12) (m3/s) | V1: enviromental discharge (Qe=Qa*0.3) (m3/s) | W1: Extraction Factor (EF) | X1: Design flow (Qd=Qa*EF) (m3/s) | Y1: Extractable discharge (Qex_m) (m3/s) Extractable discharge depends on the monthly discharge (Qm), the environmental discharge (Qe), and the design flow (Qd). | AK1: Actual extractable water volume per year (Qreal=ΣQex_m) (m3/s) | AL1: Capacity factor (CF=Qreal/Qideal) (%)
I2: January | J2: February | K2: March | L2: April | M2: May | N2: June | O2: July | P2: August | Q2: September | R2: October | S2: November | T2: December | Y2: January | Z2: February | AA2: March | AB2: April | AC2: May | AD2: June | AE2: July | AF2: August | AG2: September | AH2: October | AI2: November | AJ2: December
A3: 1 | B3: Amazon | C3: 0.68242948 | D3: -50.229459 | E3: Brazil | F3: South America | G3: South America | H3: North Atlantic Ocean | I3: 164117.08 | J3: 199312.09 | K3: 235125.97 | L3: 263221.09 | M3: 271534.16 | N3: 254402.41 | O3: 230343.61 | P3: 197705.2 | Q3: 157301.06 | R3: 120599.55 | S3: 114736.24 | T3: 132568.95 | U3: =AVERAGE(I3:T3) -> 195080.62 | V3: =U3*0.3 -> 58524.185 | W3: 28 | X3: =W3/100*U3 -> 54622.573 | Y3: 54622.574 | Z3: 54622.574 | AA3: 54622.574 | AB3: 54622.574 | AC3: 54622.574 | AD3: 54622.574 | AE3: 54622.574 | AF3: 54622.574 | AG3: 54622.574 | AH3: 54622.574 | AI3: 54622.574 | AJ3: 54622.574 | AK3: =SUM(Y3:AJ3) -> 655470.89 | AL3: =AK3/(X3*12)*100 -> 100
A4: 2 | B4: Congo | C4: -6.0787368 | D4: 12.395383 | E4: Angola | F4: Middle Africa | G4: Africa | H4: South Atlantic Ocean | I4: 47804.82 | J4: 37844.254 | K4: 34501.34 | L4: 36837.637 | M4: 38470.391 | N4: 35900.203 | O4: 31155.527 | P4: 30699.984 | Q4: 35949.352 | R4: 42605.926 | S4: 51330.012 | T4: 55939.719 | U4: =AVERAGE(I4:T4) -> 39919.93 | V4: =U4*0.3 -> 11975.979 | W4: 46 | X4: =W4/100*U4 -> 18363.168 | Y4: 18363.17 | Z4: 18363.17 | AA4: 18363.17 | AB4: 18363.17 | AC4: 18363.17 | AD4: 18363.17 | AE4: 18363.17 | AF4: 18363.17 | AG4: 18363.17 | AH4: 18363.17 | AI4: 18363.17 | AJ4: 18363.17 | AK4: =SUM(Y4:AJ4) -> 220358.04 | AL4: =AK4/(X4*12)*100 -> 100.00001
A5: 3 | B5: Orinoco | C5: 8.6194309 | D5: -60.716021 | E5: Venezuela | F5: South America | G5: South America | H5: North Atlantic Ocean | I5: 13188.122 | J5: 8861.2324 | K5: 7248.3765 | L5: 9063.8623 | M5: 19590.602 | N5: 35793.672 | O5: 53039.289 | P5: 65229.184 | Q5: 62182.836 | R5: 46353.078 | S5: 31943.396 | T5: 21467.197 | U5: =AVERAGE(I5:T5) -> 31163.404 | V5: =U5*0.3 -> 9349.0212 | W5: 72 | X5: =W5/100*U5 -> 22437.651 | Y5: 3839.1006 | Z5: 0 | AA5: 0 | AB5: 0 | AC5: 10241.58 | AD5: 22437.65 | AE5: 22437.65 | AF5: 22437.65 | AG5: 22437.65 | AH5: 22437.65 | AI5: 22437.65 | AJ5: 12118.176 | AK5: =SUM(Y5:AJ5) -> 160824.76 | AL5: =AK5/(X5*12)*100 -> 59.730242
A6: 4 | B6: Changjiang | C6: 30.272075 | D6: 120.79868 | E6: China | F6: Eastern Asia | G6: Asia | H6: North Pacific Ocean | I6: 9879.6875 | J6: 11218.508 | K6: 16066.704 | L6: 22486.77 | M6: 32156.129 | N6: 38957.23 | O6: 44882.391 | P6: 43391.727 | Q6: 39857.477 | R6: 33626.625 | S6: 23611.127 | T6: 13442.908 | U6: =AVERAGE(I6:T6) -> 27464.774 | V6: =U6*0.3 -> 8239.4321 | W6: 5 | X6: =W6/100*U6 -> 1373.2387 | Y6: 1373.2386 | Z6: 1373.2386 | AA6: 1373.2386 | AB6: 1373.2386 | AC6: 1373.2386 | AD6: 1373.2386 | AE6: 1373.2386 | AF6: 1373.2386 | AG6: 1373.2386 | AH6: 1373.2386 | AI6: 1373.2386 | AJ6: 1373.2386 | AK6: =SUM(Y6:AJ6) -> 16478.863 | AL6: =AK6/(X6*12)*100 -> 99.999994
A7: 5 | B7: Brahmaputra | C7: 22.410302 | D7: 91.075887 | E7: Bangladesh | F7: Southern Asia | G7: Asia | H7: Indian Ocean | I7: 6100.2915 | J7: 4510.332 | K7: 4070.5964 | L7: 5698.248 | M7: 9980.5576 | N7: 19485.889 | O7: 33876.707 | P7: 45211.961 | Q7: 41641.328 | R7: 36112.414 | S7: 23611.361 | T7: 10365.971 | U7: =AVERAGE(I7:T7) -> 20055.471 | V7: =U7*0.3 -> 6016.6414 | W7: 67 | X7: =W7/100*U7 -> 13437.166 | Y7: 83.650391 | Z7: 0 | AA7: 0 | AB7: 0 | AC7: 3963.9165 | AD7: 13437.165 | AE7: 13437.165 | AF7: 13437.165 | AG7: 13437.165 | AH7: 13437.165 | AI7: 13437.165 | AJ7: 4349.3296 | AK7: =SUM(Y7:AJ7) -> 89019.886 | AL7: =AK7/(X7*12)*100 -> 55.207504
A8: 6 | B8: Mississippi | C8: 29.148376 | D8: -89.248975 | E8: United States | F8: Northern America | G8: North America | H8: North Atlantic Ocean | I8: 18628.621 | J8: 21352.148 | K8: 25386.604 | L8: 27470.746 | M8: 25555.598 | N8: 20423.666 | O8: 15543.308 | P8: 10725.961 | Q8: 8729.7891 | R8: 9052.5371 | S8: 10659.257 | T8: 15165.394 | U8: =AVERAGE(I8:T8) -> 17391.136 | V8: =U8*0.3 -> 5217.3407 | W8: 20 | X8: =W8/100*U8 -> 3478.2272 | Y8: 3478.2271 | Z8: 3478.2271 | AA8: 3478.2271 | AB8: 3478.2271 | AC8: 3478.2271 | AD8: 3478.2271 | AE8: 3478.2271 | AF8: 3478.2271 | AG8: 3478.2271 | AH8: 3478.2271 | AI8: 3478.2271 | AJ8: 3478.2271 | AK8: =SUM(Y8:AJ8) -> 41738.725 | AL8: =AK8/(X8*12)*100 -> 99.999998
A9: 7 | B9: Yenisey | C9: 70.963189 | D9: 83.284515 | E9: Russia | F9: Asiatic Russia | G9: Asia | H9: Arctic Ocean | I9: 6836.1479 | J9: 6874.4268 | K9: 6710.8633 | L9: 6807.2222 | M9: 28720.305 | N9: 78429.586 | O9: 25852.654 | P9: 17296.711 | Q9: 17274.57 | R9: 14170.547 | S9: 7835.8667 | T9: 6645.1147 | U9: =AVERAGE(I9:T9) -> 18621.168 | V9: =U9*0.3 -> 5586.3504 | W9: 5 | X9: =W9/100*U9 -> 931.05839 | Y9: 931.05829 | Z9: 931.05829 | AA9: 931.05829 | AB9: 931.05829 | AC9: 931.05829 | AD9: 931.05829 | AE9: 931.05829 | AF9: 931.05829 | AG9: 931.05829 | AH9: 931.05829 | AI9: 931.05829 | AJ9: 931.05829 | AK9: =SUM(Y9:AJ9) -> 11172.699 | AL9: =AK9/(X9*12)*100 -> 99.999989
A10: 8 | B10: Parana | C10: -34.324424 | D10: -58.4795 | E10: Argentina | F10: South America | G10: South America | H10: South Atlantic Ocean | I10: 15655.203 | J10: 17266.107 | K10: 18210.176 | L10: 18381.732 | M10: 17378.078 | N10: 16651.133 | O10: 16231.979 | P10: 14415.406 | Q10: 13247.189 | R10: 13903.787 | S10: 14549.443 | T10: 14450.283 | U10: =AVERAGE(I10:T10) -> 15861.71 | V10: =U10*0.3 -> 4758.5129 | W10: 53 | X10: =W10/100*U10 -> 8406.7061 | Y10: 8406.7051 | Z10: 8406.7051 | AA10: 8406.7051 | AB10: 8406.7051 | AC10: 8406.7051 | AD10: 8406.7051 | AE10: 8406.7051 | AF10: 8406.7051 | AG10: 8406.7051 | AH10: 8406.7051 | AI10: 8406.7051 | AJ10: 8406.7051 | AK10: =SUM(Y10:AJ10) -> 100880.46 | AL10: =AK10/(X10*12)*100 -> 99.999988
A11: 9 | B11: Lena | C11: 72.558999 | D11: 129.23341 | E11: Russia | F11: Asiatic Russia | G11: Asia | H11: Arctic Ocean | I11: 3062.7576 | J11: 2436.094 | K11: 1899.5377 | L11: 1550.8582 | M11: 7358.5303 | N11: 73883.031 | O11: 39625.434 | P11: 27380.34 | Q11: 24924.809 | R11: 14800.756 | S11: 3686.3613 | T11: 3148.4214 | U11: =AVERAGE(I11:T11) -> 16979.744 | V11: =U11*0.3 -> 5093.9233 | W11: 100 | X11: =W11/100*U11 -> 16979.744 | Y11: 0 | Z11: 0 | AA11: 0 | AB11: 0 | AC11: 2264.6069 | AD11: 16979.744 | AE11: 16979.744 | AF11: 16979.744 | AG11: 16979.744 | AH11: 9706.832 | AI11: 0 | AJ11: 0 | AK11: =SUM(Y11:AJ11) -> 79890.415 | AL11: =AK11/(X11*12)*100 -> 39.208686
A12: 10 | B12: Mekong | C12: 9.8199719 | D12: 106.51762 | E12: Vietnam | F12: Southeastern Asia | G12: Asia | H12: South China and Easter Archipelagic Seas | I12: 2793.1201 | J12: 2149.3745 | K12: 1807.7325 | L12: 1786.6724 | M12: 2922.5596 | N12: 8942.7891 | O12: 17380.783 | P12: 27390.908 | Q12: 27577.334 | R12: 16108.361 | S12: 8031.4658 | T12: 4265.9014 | U12: =AVERAGE(I12:T12) -> 10096.417 | V12: =U12*0.3 -> 3028.925 | W12: 58 | X12: =W12/100*U12 -> 5855.9217 | Y12: 0 | Z12: 0 | AA12: 0 | AB12: 0 | AC12: 0 | AD12: 5855.9219 | AE12: 5855.9219 | AF12: 5855.9219 | AG12: 5855.9219 | AH12: 5855.9219 | AI12: 5002.541 | AJ12: 1236.9763 | AK12: =SUM(Y12:AJ12) -> 35519.127 | AL12: =AK12/(X12*12)*100 -> 50.545881
A13: 11 | B13: Tocantins | C13: -1.5396851 | D13: -48.878388 | E13: Brazil | F13: South America | G13: South America | H13: South Atlantic Ocean | I13: 13302.817 | J13: 18844.254 | K13: 22507.922 | L13: 22481.84 | M13: 14927.415 | N13: 7337.1875 | O13: 4729.7427 | P13: 3887.0452 | Q13: 3505.3059 | R13: 3610.6501 | S13: 4991.2476 | T13: 8004.9038 | U13: =AVERAGE(I13:T13) -> 10677.528 | V13: =U13*0.3 -> 3203.2583 | W13: 2 | X13: =W13/100*U13 -> 213.55055 | Y13: 213.55055 | Z13: 213.55055 | AA13: 213.55055 | AB13: 213.55055 | AC13: 213.55055 | AD13: 213.55055 | AE13: 213.55055 | AF13: 213.55055 | AG13: 213.55055 | AH13: 213.55055 | AI13: 213.55055 | AJ13: 213.55055 | AK13: =SUM(Y13:AJ13) -> 2562.6066 | AL13: =AK13/(X13*12)*100 -> 99.999999
A14: 12 | B14: Ob | C14: 66.453033 | D14: 71.005041 | E14: Russia | F14: Asiatic Russia | G14: Asia | H14: Arctic Ocean | I14: 4878.6313 | J14: 4149.2183 | K14: 3646.0854 | L14: 3848.7908 | M14: 16077.431 | N14: 33398.926 | O14: 29659.504 | P14: 21902.992 | Q14: 13887.227 | R14: 10514.106 | S14: 6686.7144 | T14: 5566.2119 | U14: =AVERAGE(I14:T14) -> 12851.32 | V14: =U14*0.3 -> 3855.396 | W14: 13 | X14: =W14/100*U14 -> 1670.6716 | Y14: 1023.2354 | Z14: 293.82227 | AA14: 0 | AB14: 0 | AC14: 1670.6716 | AD14: 1670.6716 | AE14: 1670.6716 | AF14: 1670.6716 | AG14: 1670.6716 | AH14: 1670.6716 | AI14: 1670.6716 | AJ14: 1670.6716 | AK14: =SUM(Y14:AJ14) -> 14682.43 | AL14: =AK14/(X14*12)*100 -> 73.23617
... A238: 236 | B238: Kymi | C238: 40.387513 | D238: 16.857027 | E238: Italy | F238: Southern Europe | G238: Europe | H238: Mediterranean Region | I238: 297.21002 | J238: 296.20981 | K238: 286.14905 | L238: 303.55411 | M238: 343.77658 | N238: 358.4678 | O238: 336.57654 | P238: 301.26584 | Q238: 274.0011 | R238: 263.95898 | S238: 275.11588 | T238: 289.49506 | U238: =AVERAGE(I238:T238) -> 302.1484 | V238: =U238*0.3 -> 90.644519 | W238: 57 | X238: =W238/100*U238 -> 172.22459 | Y238: 172.22459 | Z238: 172.22459 | AA238: 172.22459 | AB238: 172.22459 | AC238: 172.22459 | AD238: 172.22459 | AE238: 172.22459 | AF238: 172.22459 | AG238: 172.22459 | AH238: 172.22459 | AI238: 172.22459 | AJ238: 172.22459 | AK238: =SUM(Y238:AJ238) -> 2066.6951 | AL238: =AK238/(X238*12)*100 -> 100
A239: 237 | B239: Sittang | C239: 17.186302 | D239: 96.894033 | E239: Myanmar | F239: Southeastern Asia | G239: Asia | H239: Indian Ocean | I239: NaN | J239: NaN | K239: NaN | L239: NaN | M239: NaN | N239: NaN | O239: NaN | P239: NaN | Q239: NaN | R239: NaN | S239: NaN | T239: NaN | U239: =AVERAGE(I239:T239) -> #DIV/0! | V239: =U239*0.3 -> #DIV/0! | W239: 0 | X239: =W239/100*U239 -> #DIV/0! | Y239: 0 | Z239: 0 | AA239: 0 | AB239: 0 | AC239: 0 | AD239: 0 | AE239: 0 | AF239: 0 | AG239: 0 | AH239: 0 | AI239: 0 | AJ239: 0 | AK239: =SUM(Y239:AJ239) -> 0 | AL239: NaN
A240: 238 | B240: Damodar | C240: 21.909277 | D240: 88.096432 | E240: India | F240: Southern Asia | G240: Asia | H240: Indian Ocean | I240: 32.439026 | J240: 28.463415 | K240: 23.299999 | L240: 21.390244 | M240: 37.275002 | N240: 195.48781 | O240: 698.56097 | P240: 1038.561 | Q240: 941.43903 | R240: 398.46155 | S240: 95.414635 | T240: 45.048782 | U240: =AVERAGE(I240:T240) -> 296.32012 | V240: =U240*0.3 -> 88.896037 | W240: 100 | X240: =W240/100*U240 -> 296.32012 | Y240: 0 | Z240: 0 | AA240: 0 | AB240: 0 | AC240: 0 | AD240: 106.59178 | AE240: 296.3201 | AF240: 296.3201 | AG240: 296.3201 | AH240: 296.3201 | AI240: 6.5186081 | AJ240: 0 | AK240: =SUM(Y240:AJ240) -> 1298.3908 | AL240: =AK240/(X240*12)*100 -> 36.514305
A241: 239 | B241: Minho (Mino) | C241: 41.86529 | D241: -8.8694139 | E241: Portugal | F241: Southern Europe | G241: Europe | H241: North Atlantic Ocean | I241: 742.703 | J241: 869.30835 | K241: 695.94543 | L241: 553.65759 | M241: 384.4682 | N241: 243.98404 | O241: 140.87158 | P241: 96.269638 | Q241: 105.71023 | R241: 174.52188 | S241: 357.60364 | T241: 623.97345 | U241: =AVERAGE(I241:T241) -> 415.75142 | V241: =U241*0.3 -> 124.72543 | W241: 28 | X241: =W241/100*U241 -> 116.4104 | Y241: 116.4104 | Z241: 116.4104 | AA241: 116.4104 | AB241: 116.4104 | AC241: 116.4104 | AD241: 116.4104 | AE241: 16.146149 | AF241: 0 | AG241: 0 | AH241: 49.796448 | AI241: 116.4104 | AJ241: 116.4104 | AK241: =SUM(Y241:AJ241) -> 997.2258 | AL241: =AK241/(X241*12)*100 -> 71.387223
A242: 240 | B242: Nagdong (Nakdon | C242: 35.123292 | D242: 128.95564 | E242: South Korea | F242: Eastern Asia | G242: Asia | H242: North Pacific Ocean | I242: 74.388885 | J242: 98.444443 | K242: 165.52632 | L242: 271.57895 | M242: 188.63158 | N242: 202.64999 | O242: 830.94739 | P242: 559.40002 | Q242: 609.63159 | R242: 224.6842 | S242: 143.52632 | T242: 109.68421 | U242: =AVERAGE(I242:T242) -> 289.92449 | V242: =U242*0.3 -> 86.977347 | W242: 7 | X242: =W242/100*U242 -> 20.294714 | Y242: 0 | Z242: 11.467094 | AA242: 20.294716 | AB242: 20.294716 | AC242: 20.294716 | AD242: 20.294716 | AE242: 20.294716 | AF242: 20.294716 | AG242: 20.294716 | AH242: 20.294716 | AI242: 20.294716 | AJ242: 20.294716 | AK242: =SUM(Y242:AJ242) -> 214.41425 | AL242: =AK242/(X242*12)*100 -> 88.041912
A243: 241 | B243: Patía | C243: 2.5238124 | D243: -78.319381 | E243: Colombia | F243: South America | G243: South America | H243: North Pacific Ocean | I243: 331.76923 | J243: 299.69232 | K243: 289.61539 | L243: 377.81818 | M243: 380.09091 | N243: 266.53845 | O243: 222.30769 | P243: 169.07692 | Q243: 152.61539 | R243: 241.58333 | S243: 367 | T243: 387.16666 | U243: =AVERAGE(I243:T243) -> 290.43954 | V243: =U243*0.3 -> 87.131862 | W243: 22 | X243: =W243/100*U243 -> 63.896699 | Y243: 63.896698 | Z243: 63.896698 | AA243: 63.896698 | AB243: 63.896698 | AC243: 63.896698 | AD243: 63.896698 | AE243: 63.896698 | AF243: 63.896698 | AG243: 63.896698 | AH243: 63.896698 | AI243: 63.896698 | AJ243: 63.896698 | AK243: =SUM(Y243:AJ243) -> 766.76038 | AL243: =AK243/(X243*12)*100 -> 99.999999
A244: 242 | B244: Pearl | C244: 30.191694 | D244: -89.585502 | E244: United States | F244: Northern America | G244: North America | H244: North Atlantic Ocean | I244: 428.0943 | J244: 562.12878 | K244: 584.56775 | L244: 524.69769 | M244: 314.33112 | N244: 158.75191 | O244: 130.50023 | P244: 107.92136 | Q244: 97.958 | R244: 92.125244 | S244: 121.0537 | T244: 276.65738 | U244: =AVERAGE(I244:T244) -> 283.23229 | V244: =U244*0.3 -> 84.969687 | W244: 2 | X244: =W244/100*U244 -> 5.6646458 | Y244: 5.6646461 | Z244: 5.6646461 | AA244: 5.6646461 | AB244: 5.6646461 | AC244: 5.6646461 | AD244: 5.6646461 | AE244: 5.6646461 | AF244: 5.6646461 | AG244: 5.6646461 | AH244: 5.6646461 | AI244: 5.6646461 | AJ244: 5.6646461 | AK244: =SUM(Y244:AJ244) -> 67.975753 | AL244: =AK244/(X244*12)*100 -> 100.00001
A245: 243 | B245: Pascagoula | C245: 30.388523 | D245: -88.606592 | E245: United States | F245: Northern America | G245: North America | H245: North Atlantic Ocean | I245: 418.94812 | J245: 526.04303 | K245: 570.21118 | L245: 510.22311 | M245: 288.30453 | N245: 158.37086 | O245: 153.24716 | P245: 112.62922 | Q245: 113.89764 | R245: 89.055031 | S245: 137.74332 | T245: 284.66684 | U245: =AVERAGE(I245:T245) -> 280.27834 | V245: =U245*0.3 -> 84.083501 | W245: 1 | X245: =W245/100*U245 -> 2.8027834 | Y245: 2.8027833 | Z245: 2.8027833 | AA245: 2.8027833 | AB245: 2.8027833 | AC245: 2.8027833 | AD245: 2.8027833 | AE245: 2.8027833 | AF245: 2.8027833 | AG245: 2.8027833 | AH245: 2.8027833 | AI245: 2.8027833 | AJ245: 2.8027833 | AK245: =SUM(Y245:AJ245) -> 33.6334 | AL245: =AK245/(X245*12)*100 -> 99.999998
A246: 244 | B246: Pee Dee | C246: 33.375775 | D246: -79.26363 | E246: United States | F246: Northern America | G246: North America | H246: North Atlantic Ocean | I246: 550.62036 | J246: 691.83911 | K246: 766.78467 | L246: 625.46558 | M246: 396.22778 | N246: 308.08026 | O246: 282.66702 | P246: 287.32086 | Q246: 275.39545 | R246: 259.41547 | S246: 274.52295 | T246: 379.58295 | U246: =AVERAGE(I246:T246) -> 424.82687 | V246: =U246*0.3 -> 127.44806 | W246: 31 | X246: =W246/100*U246 -> 131.69633 | Y246: 131.69633 | Z246: 131.69633 | AA246: 131.69633 | AB246: 131.69633 | AC246: 131.69633 | AD246: 131.69633 | AE246: 131.69633 | AF246: 131.69633 | AG246: 131.69633 | AH246: 131.69633 | AI246: 131.69633 | AJ246: 131.69633 | AK246: =SUM(Y246:AJ246) -> 1580.356 | AL246: =AK246/(X246*12)*100 -> 100
A247: 245 | B247: Kem | C247: 64.94375 | D247: 34.749528 | E247: Russia | F247: European Russia | G247: Europe | H247: Arctic Ocean | I247: 159.45384 | J247: 133.22 | K247: 109.63594 | L247: 142.3 | M247: 503.80951 | N247: 493.63492 | O247: 362.2381 | P247: 280.79688 | Q247: 266.29688 | R247: 277.19061 | S247: 255.25626 | T247: 198.98593 | U247: =AVERAGE(I247:T247) -> 265.23491 | V247: =U247*0.3 -> 79.570472 | W247: 11 | X247: =W247/100*U247 -> 29.17584 | Y247: 29.175838 | Z247: 29.175838 | AA247: 29.175838 | AB247: 29.175838 | AC247: 29.175838 | AD247: 29.175838 | AE247: 29.175838 | AF247: 29.175838 | AG247: 29.175838 | AH247: 29.175838 | AI247: 29.175838 | AJ247: 29.175838 | AK247: =SUM(Y247:AJ247) -> 350.11006 | AL247: =AK247/(X247*12)*100 -> 99.999994
A248: 246 | B248: Waiau (S) | C248: -44.604167 | D248: 167.825 | E248: New Zealand | F248: Australia/New Zealand | G248: Oceania | H248: South Pacific Ocean | I248: 317.96588 | J248: 317.51181 | K248: 312.48419 | L248: 321.76315 | M248: 314.71802 | N248: 275.3985 | O248: 241.8102 | P248: 236.85316 | Q248: 287.35715 | R248: 357.54587 | S248: 378.91382 | T248: 362.99924 | U248: =AVERAGE(I248:T248) -> 310.44342 | V248: =U248*0.3 -> 93.133025 | W248: 46 | X248: =W248/100*U248 -> 142.80397 | Y248: 142.80399 | Z248: 142.80399 | AA248: 142.80399 | AB248: 142.80399 | AC248: 142.80399 | AD248: 142.80399 | AE248: 142.80399 | AF248: 142.80399 | AG248: 142.80399 | AH248: 142.80399 | AI248: 142.80399 | AJ248: 142.80399 | AK248: =SUM(Y248:AJ248) -> 1713.6479 | AL248: =AK248/(X248*12)*100 -> 100.00001
A249: 247 | B249: Ntem | C249: 2.2958238 | D249: 9.8512239 | E249: Cameroon | F249: Middle Africa | G249: Africa | H249: North Atlantic Ocean | I249: 134.45 | J249: 109.07307 | K249: 159.31923 | L249: 273.34616 | M249: 336.26923 | N249: 315.53845 | O249: 189.70741 | P249: 90.637039 | Q249: 224.9037 | R249: 558 | S249: 594.22223 | T249: 321.7037 | U249: =AVERAGE(I249:T249) -> 275.59752 | V249: =U249*0.3 -> 82.679255 | W249: 2 | X249: =W249/100*U249 -> 5.5119504 | Y249: 5.51195 | Z249: 5.51195 | AA249: 5.51195 | AB249: 5.51195 | AC249: 5.51195 | AD249: 5.51195 | AE249: 5.51195 | AF249: 5.51195 | AG249: 5.51195 | AH249: 5.51195 | AI249: 5.51195 | AJ249: 5.51195 | AK249: =SUM(Y249:AJ249) -> 66.1434 | AL249: =AK249/(X249*12)*100 -> 99.999993
A250: 248 | B250: Mae Klong | C250: 13.366663 | D250: 99.996802 | E250: Thailand | F250: Southeastern Asia | G250: Asia | H250: South China and Easter Archipelagic Seas | I250: 133.62581 | J250: 129.7811 | K250: 244.67957 | L250: 359.75482 | M250: 614.83624 | N250: 582.64636 | O250: 501.784 | P250: 248.99896 | Q250: 166.98137 | R250: 125.32672 | S250: 84.594032 | T250: 96.223778 | U250: =AVERAGE(I250:T250) -> 274.10273 | V250: =U250*0.3 -> 82.230819 | W250: 15 | X250: =W250/100*U250 -> 41.115409 | Y250: 41.11541 | Z250: 41.11541 | AA250: 41.11541 | AB250: 41.11541 | AC250: 41.11541 | AD250: 41.11541 | AE250: 41.11541 | AF250: 41.11541 | AG250: 41.11541 | AH250: 41.11541 | AI250: 2.3632126 | AJ250: 13.992958 | AK250: =SUM(Y250:AJ250) -> 427.51027 | AL250: =AK250/(X250*12)*100 -> 86.648428
A251: 249 | B251: Cagayan | C251: 18.337248 | D251: 121.63323 | E251: Philippines | F251: Southeastern Asia | G251: Asia | H251: South China and Easter Archipelagic Seas | I251: 208.58333 | J251: 123.16666 | K251: 132.83333 | L251: 79.75 | M251: 94.083336 | N251: 133.295 | O251: 269.39999 | P251: 169.3 | Q251: 282.60001 | R251: 574.59998 | S251: 706.59998 | T251: 481.39999 | U251: =AVERAGE(I251:T251) -> 271.30097 | V251: =U251*0.3 -> 81.39029 | W251: 15 | X251: =W251/100*U251 -> 40.695145 | Y251: 40.695141 | Z251: 40.695141 | AA251: 40.695141 | AB251: 0 | AC251: 12.693054 | AD251: 40.695141 | AE251: 40.695141 | AF251: 40.695141 | AG251: 40.695141 | AH251: 40.695141 | AI251: 40.695141 | AJ251: 40.695141 | AK251: =SUM(Y251:AJ251) -> 419.64446 | AL251: =AK251/(X251*12)*100 -> 85.93254
... A457: 455 | B457: Kiiminki | C457: 65.196326 | D457: 25.301698 | E457: Finland | F457: Northern Europe | G457: Europe | H457: Baltic Sea | I457: 17.956896 | J457: 10.727103 | K457: 8.9891033 | L457: 59.871872 | M457: 161.62889 | N457: 59.967186 | O457: 26.467232 | P457: 26.51964 | Q457: 33.571827 | R457: 44.819523 | S457: 48.679298 | T457: 33.644356 | U457: =AVERAGE(I457:T457) -> 44.403577 | V457: =U457*0.3 -> 13.321073 | W457: 29 | X457: =W457/100*U457 -> 12.877037 | Y457: 4.6358223 | Z457: 0 | AA457: 0 | AB457: 12.877038 | AC457: 12.877038 | AD457: 12.877038 | AE457: 12.877038 | AF457: 12.877038 | AG457: 12.877038 | AH457: 12.877038 | AI457: 12.877038 | AJ457: 12.877038 | AK457: =SUM(Y457:AJ457) -> 120.52916 | AL457: =AK457/(X457*12)*100 -> 78.000061
A458: 456 | B458: Tuxpan | C458: 20.96598 | D458: -97.315251 | E458: Mexico | F458: Central America | G458: North America | H458: North Atlantic Ocean | I458: 21.625 | J458: 17.875 | K458: 16.375 | L458: 14.125 | M458: 21.4 | N458: 61.5 | O458: 124 | P458: 47.5 | Q458: NaN | R458: 58 | S458: 87.5 | T458: 54.875 | U458: =AVERAGE(I458:T458) -> 47.706818 | V458: =U458*0.3 -> 14.312045 | W458: 4 | X458: =W458/100*U458 -> 1.9082727 | Y458: 1.9082729 | Z458: 1.9082729 | AA458: 1.9082729 | AB458: 0 | AC458: 1.9082729 | AD458: 1.9082729 | AE458: 1.9082729 | AF458: 1.9082729 | AG458: NaN | AH458: 1.9082729 | AI458: 1.9082729 | AJ458: 1.9082729 | AK458: =SUM(Y458:AJ458) -> 19.082729 | AL458: =AK458/(X458*12)*100 -> 83.333341
A459: 457 | B459: Var | C459: 43.655562 | D459: 7.1995599 | E459: France | F459: Western Europe | G459: Europe | H459: Mediterranean Region | I459: 34.033333 | J459: 43.566666 | K459: 53.933334 | L459: 45.866669 | M459: 72.733337 | N459: 79.166664 | O459: 40.900002 | P459: 23.833334 | Q459: 18.199999 | R459: 54.599998 | S459: 31.200001 | T459: 22.766666 | U459: =AVERAGE(I459:T459) -> 43.4 | V459: =U459*0.3 -> 13.02 | W459: 11 | X459: =W459/100*U459 -> 4.774 | Y459: 4.7740006 | Z459: 4.7740006 | AA459: 4.7740006 | AB459: 4.7740006 | AC459: 4.7740006 | AD459: 4.7740006 | AE459: 4.7740006 | AF459: 4.7740006 | AG459: 4.7740006 | AH459: 4.7740006 | AI459: 4.7740006 | AJ459: 4.7740006 | AK459: =SUM(Y459:AJ459) -> 57.288007 | AL459: =AK459/(X459*12)*100 -> 100.00001
A460: 458 | B460: Yeong San | C460: 34.933333 | D460: 126.52917 | E460: South Korea | F460: Eastern Asia | G460: Asia | H460: North Pacific Ocean | I460: 20 | J460: 36.75 | K460: 26.75 | L460: 53.75 | M460: 32 | N460: 93 | O460: 51.25 | P460: 76.5 | Q460: 54.5 | R460: 25.25 | S460: 22.75 | T460: 21.75 | U460: =AVERAGE(I460:T460) -> 42.854167 | V460: =U460*0.3 -> 12.85625 | W460: 16 | X460: =W460/100*U460 -> 6.8566667 | Y460: 6.856667 | Z460: 6.856667 | AA460: 6.856667 | AB460: 6.856667 | AC460: 6.856667 | AD460: 6.856667 | AE460: 6.856667 | AF460: 6.856667 | AG460: 6.856667 | AH460: 6.856667 | AI460: 6.856667 | AJ460: 6.856667 | AK460: =SUM(Y460:AJ460) -> 82.280004 | AL460: =AK460/(X460*12)*100 -> 100
A461: 459 | B461: Coco | C461: 13.095833 | D461: -87.3375 | E461: Honduras | F461: Central America | G461: North America | H461: North Pacific Ocean | I461: 10.361923 | J461: 6.6484613 | K461: 4.9719229 | L461: 5.9752398 | M461: 44.661602 | N461: 40.167202 | O461: 39.07468 | P461: 49.245384 | Q461: 81.533806 | R461: 80.703163 | S461: 25.541924 | T461: 13.886154 | U461: =AVERAGE(I461:T461) -> 33.564288 | V461: =U461*0.3 -> 10.069287 | W461: 86 | X461: =W461/100*U461 -> 28.865288 | Y461: 0.29263687 | Z461: 0 | AA461: 0 | AB461: 0 | AC461: 28.865288 | AD461: 28.865288 | AE461: 28.865288 | AF461: 28.865288 | AG461: 28.865288 | AH461: 28.865288 | AI461: 15.472637 | AJ461: 3.8168678 | AK461: =SUM(Y461:AJ461) -> 192.77387 | AL461: =AK461/(X461*12)*100 -> 55.653313
A462: 460 | B462: Palyavaam | C462: 68.863722 | D462: 170.44658 | E462: Russia | F462: Asiatic Russia | G462: Asia | H462: Arctic Ocean | I462: 0.001 | J462: 0.001 | K462: 0.001 | L462: 0.001 | M462: 12.6544 | N462: 187.09599 | O462: 131.95599 | P462: 110.056 | Q462: 49.084 | R462: 12.7192 | S462: 2.5616 | T462: 0.11826087 | U462: =AVERAGE(I462:T462) -> 42.187453 | V462: =U462*0.3 -> 12.656236 | W462: 100 | X462: =W462/100*U462 -> 42.187453 | Y462: 0 | Z462: 0 | AA462: 0 | AB462: 0 | AC462: 0 | AD462: 42.187458 | AE462: 42.187458 | AF462: 42.187458 | AG462: 36.427761 | AH462: 0.062962532 | AI462: 0 | AJ462: 0 | AK462: =SUM(Y462:AJ462) -> 163.0531 | AL462: =AK462/(X462*12)*100 -> 32.208055
A463: 461 | B463: Kikuchi | C463: 32.9 | D463: 130.54167 | E463: Japan | F463: Eastern Asia | G463: Asia | H463: North Pacific Ocean | I463: 18.041267 | J463: 17.9242 | K463: 21.310467 | L463: 27.521732 | M463: 38.6628 | N463: 67.685135 | O463: 119.88333 | P463: 55.903267 | Q463: 37.002468 | R463: 28.649532 | S463: 24.450142 | T463: 19.033358 | U463: =AVERAGE(I463:T463) -> 39.672308 | V463: =U463*0.3 -> 11.901692 | W463: 15 | X463: =W463/100*U463 -> 5.9508462 | Y463: 5.9508457 | Z463: 5.9508457 | AA463: 5.9508457 | AB463: 5.9508457 | AC463: 5.9508457 | AD463: 5.9508457 | AE463: 5.9508457 | AF463: 5.9508457 | AG463: 5.9508457 | AH463: 5.9508457 | AI463: 5.9508457 | AJ463: 5.9508457 | AK463: =SUM(Y463:AJ463) -> 71.410148 | AL463: =AK463/(X463*12)*100 -> 99.999991
A464: 462 | B464: Candelaria | C464: 18.619947 | D464: -91.244106 | E464: Mexico | F464: Central America | G464: North America | H464: North Atlantic Ocean | I464: 29.625 | J464: 20 | K464: 19.375 | L464: 16.375 | M464: 15 | N464: 20.25 | O464: 33.5 | P464: 33.5 | Q464: 61.625 | R464: 98.875 | S464: 86.125 | T464: 64.5 | U464: =AVERAGE(I464:T464) -> 41.5625 | V464: =U464*0.3 -> 12.46875 | W464: 6 | X464: =W464/100*U464 -> 2.49375 | Y464: 2.4937501 | Z464: 2.4937501 | AA464: 2.4937501 | AB464: 2.4937501 | AC464: 2.4937501 | AD464: 2.4937501 | AE464: 2.4937501 | AF464: 2.4937501 | AG464: 2.4937501 | AH464: 2.4937501 | AI464: 2.4937501 | AJ464: 2.4937501 | AK464: =SUM(Y464:AJ464) -> 29.925001 | AL464: =AK464/(X464*12)*100 -> 100
A465: 463 | B465: Almas [das] (Je | C465: -13.554167 | D465: -39.0875 | E465: Brazil | F465: South America | G465: South America | H465: South Atlantic Ocean | I465: 35.866333 | J465: 34.976444 | K465: 38.638287 | L465: 46.226601 | M465: 41.653137 | N465: 44.053574 | O465: 52.551216 | P465: 50.357677 | Q465: 41.236645 | R465: 35.47102 | S465: 38.431183 | T465: 40.454823 | U465: =AVERAGE(I465:T465) -> 41.659745 | V465: =U465*0.3 -> 12.497924 | W465: 53 | X465: =W465/100*U465 -> 22.079665 | Y465: 22.079664 | Z465: 22.079664 | AA465: 22.079664 | AB465: 22.079664 | AC465: 22.079664 | AD465: 22.079664 | AE465: 22.079664 | AF465: 22.079664 | AG465: 22.079664 | AH465: 22.079664 | AI465: 22.079664 | AJ465: 22.079664 | AK465: =SUM(Y465:AJ465) -> 264.95597 | AL465: =AK465/(X465*12)*100 -> 99.999996
A466: 464 | B466: Sinaloa | C466: 25.283096 | D466: -108.49434 | E466: Mexico | F466: Central America | G466: North America | H466: North Pacific Ocean | I466: 46.224998 | J466: 23.491667 | K466: 12.269167 | L466: 4.7861114 | M466: 4.3413887 | N466: 11.458333 | O466: 75.544441 | P466: 120.36667 | Q466: 100.09167 | R466: 44.002777 | S466: 15.394444 | T466: 34.131428 | U466: =AVERAGE(I466:T466) -> 41.008591 | V466: =U466*0.3 -> 12.302577 | W466: 82 | X466: =W466/100*U466 -> 33.627045 | Y466: 33.627048 | Z466: 11.189089 | AA466: 0 | AB466: 0 | AC466: 0 | AD466: 0 | AE466: 33.627048 | AF466: 33.627048 | AG466: 33.627048 | AH466: 31.700199 | AI466: 3.0918665 | AJ466: 21.82885 | AK466: =SUM(Y466:AJ466) -> 202.3182 | AL466: =AK466/(X466*12)*100 -> 50.137768
A467: 465 | B467: Trang | C467: 7.3958333 | D467: 99.5125 | E467: Thailand | F467: Southeastern Asia | G467: Asia | H467: South China and Easter Archipelagic Seas | I467: 47.047058 | J467: 12.44375 | K467: 7.5266666 | L467: 7.0882354 | M467: 15.611765 | N467: 21.847059 | O467: 35.894119 | P467: 34.35294 | Q467: 48.452942 | R467: 70.394119 | S467: 105.62353 | T467: 81.935295 | U467: =AVERAGE(I467:T467) -> 40.68479 | V467: =U467*0.3 -> 12.205437 | W467: 23 | X467: =W467/100*U467 -> 9.3575017 | Y467: 9.357501 | Z467: 0.23831367 | AA467: 0 | AB467: 0 | AC467: 3.4063282 | AD467: 9.357501 | AE467: 9.357501 | AF467: 9.357501 | AG467: 9.357501 | AH467: 9.357501 | AI467: 9.357501 | AJ467: 9.357501 | AK467: =SUM(Y467:AJ467) -> 78.50465 | AL467: =AK467/(X467*12)*100 -> 69.912402
A468: 466 | B468: Midori | C468: 32.498351 | D468: 130.62076 | E468: Japan | F468: Eastern Asia | G468: Asia | H468: North Pacific Ocean | I468: 15.6622 | J468: 16.2666 | K468: 18.6826 | L468: 24.858801 | M468: 24.795601 | N468: 82.990601 | O468: 138.12939 | P468: 70.092003 | Q468: 41.120998 | R468: 20.3466 | S468: 17.818001 | T468: 16.3256 | U468: =AVERAGE(I468:T468) -> 40.59075 | V468: =U468*0.3 -> 12.177225 | W468: 8 | X468: =W468/100*U468 -> 3.24726 | Y468: 3.2472599 | Z468: 3.2472599 | AA468: 3.2472599 | AB468: 3.2472599 | AC468: 3.2472599 | AD468: 3.2472599 | AE468: 3.2472599 | AF468: 3.2472599 | AG468: 3.2472599 | AH468: 3.2472599 | AI468: 3.2472599 | AJ468: 3.2472599 | AK468: =SUM(Y468:AJ468) -> 38.967119 | AL468: =AK468/(X468*12)*100 -> 99.999998
...

Sheet SGE density
A1: River ID | B1: River name | C1: Country | D1: Ocean Basin | E1: Energy Density (MJ/m3) (see the associated research paper for details on the methodology)
E2: January | F2: February | G2: March | H2: April | I2: May | J2: June | K2: July | L2: August | M2: September | N2: October | O2: November | P2: December
A3: 1 | B3: Amazon | C3: Brazil | D3: North Atlantic Ocean | E3: 1.827365 | F3: 1.823298 | G3: 1.8222897 | H3: 1.8043659 | I3: 1.8493128 | J3: 1.9987062 | K3: 2.1135864 | L3: 2.199579 | M3: 2.2207629 | N3: 2.2242432 | O3: 2.2219565 | P3: 2.2020698
A4: 2 | B4: Congo | C4: Angola | D4: South Atlantic Ocean | E4: 1.7969048 | F4: 1.8387251 | G4: 1.9182781 | H4: 1.9933208 | I4: 2.1534899 | J4: 2.2113446 | K4: 2.2307123 | L4: 2.1993293 | M4: 2.1124653 | N4: 2.065475 | O4: 2.1000635 | P4: 2.0677921
A5: 3 | B5: Orinoco | C5: Venezuela | D5: North Atlantic Ocean | E5: 1.7924595 | F5: 2.0061706 | G5: 2.029936 | H5: 2.023006 | I5: 1.9778952 | J5: 1.8254139 | K5: 1.8890276 | L5: 1.7916918 | M5: 1.9374598 | N5: 2.1011851 | O5: 2.1040468 | P5: 2.1153028
A6: 4 | B6: Changjiang | C6: China | D6: North Pacific Ocean | E6: 1.6834994 | F6: 1.7120678 | G6: 1.7131897 | H6: 1.7526 | I6: 1.8234538 | J6: 1.8515053 | K6: 1.8813777 | L6: 2.0100846 | M6: 1.8822137 | N6: 1.8452436 | O6: 1.8146613 | P6: 1.7587954
A7: 5 | B7: Brahmaputra | C7: Bangladesh | D7: Indian Ocean | E7: 1.6661784 | F7: 1.7780079 | G7: 1.8534116 | H7: 1.900203 | I7: 1.9115075 | J7: 1.8600695 | K7: 1.7892036 | L7: 1.8038062 | M7: 1.7955035 | N7: 1.8067208 | O7: 1.7697118 | P7: 1.7203006
A8: 6 | B8: Mississippi | C8: United States | D8: North Atlantic Ocean | E8: 1.8798948 | F8: 1.8344269 | G8: 1.7396389 | H8: 1.8558395 | I8: 1.9408699 | J8: 1.7899198 | K8: 1.8040607 | L8: 1.7797009 | M8: 1.9802667 | N8: 2.039438 | O8: 2.025393 | P8: 1.9883149
A9: 7 | B9: Yenisey | C9: Russia | D9: Arctic Ocean | E9: 1.9716302 | F9: 1.7518459 | G9: 1.8189378 | H9: 1.7652381 | I9: 1.8114089 | J9: 1.6713123 | K9: 1.9847719 | L9: 1.9521637 | M9: 1.9449488 | N9: 1.9285149 | O9: 1.7564762 | P9: 1.7203234
A10: 8 | B10: Parana | C10: Argentina | D10: South Atlantic Ocean | E10: 1.8757285 | F10: 1.9176478 | G10: 1.9172615 | H10: 1.8001786 | I10: 1.9060754 | J10: 2.0164675 | K10: 2.0570352 | L10: 2.0313218 | M10: 2.0350498 | N10: 2.0121278 | O10: 1.8472386 | P10: 1.9713432
A11: 9 | B11: Lena | C11: Russia | D11: Arctic Ocean | E11: 1.7952416 | F11: 1.7248873 | G11: 1.8954004 | H11: 1.8662535 | I11: 1.8937165 | J11: 1.888285 | K11: 1.8568707 | L11: 1.8189089 | M11: 1.7992323 | N11: 1.8032522 | O11: 1.7839918 | P11: 1.7836229
A12: 10 | B12: Mekong | C12: Vietnam | D12: South China and Easter Archipelagic Seas | E12: 2.0301534 | F12: 2.0657153 | G12: 2.0470578 | H12: 2.0185917 | I12: 1.9603922 | J12: 1.9634933 | K12: 1.8148414 | L12: 1.8155604 | M12: 1.8373858 | N12: 1.8295025 | O12: 1.9654629 | P12: 1.9757779
A13: 11 | B13: Tocantins | C13: Brazil | D13: South Atlantic Ocean | E13: 1.834581 | F13: 1.8256743 | G13: 1.8558598 | H13: 1.8057717 | I13: 2.1224128 | J13: 2.1812831 | K13: 2.2078102 | L13: 2.2171766 | M13: 2.2160871 | N13: 2.2087259 | O13: 2.2118872 | P13: 2.2057911
A14: 12 | B14: Ob | C14: Russia | D14: Arctic Ocean | E14: 1.645837 | F14: 1.8120813 | G14: 1.8710044 | H14: 1.7711858 | I14: 1.9086516 | J14: 1.8809129 | K14: 1.7916694 | L14: 1.7790158 | M14: 1.8058899 | N14: 1.8168196 | O14: 1.8050513 | P14: 1.802658
... A1080: 1078 | B1080: Rio Caroni | C1080: Trinidad and Tobago | D1080: North Atlantic Ocean | E1080: 1.9926026 | F1080: 2.0480832 | G1080: 2.0626212 | H1080: 2.102738 | I1080: 2.0808824 | J1080: 1.9701186 | K1080: 1.8538218 | L1080: 1.8382298 | M1080: 1.802572 | N1080: 1.8860644 | O1080: 2.0132034 | P1080: 2.1119844

Sheet Theoretical SGE potential
A1: River ID | B1: River name | C1: Country | D1: Ocean Basin | E1: Theoretical SGE Potential (MW) (see the associated research paper for details on the methodology)
E2: January | F2: February | G2: March | H2: April | I2: May | J2: June | K2: July | L2: August | M2: September | N2: October | O2: November | P2: December | Q2: Average
A3: 1 | B3: Amazon | C3: Brazil | D3: North Atlantic Ocean | E3: =Rivers!I3*'SGE density'!E3 -> 299901.81 | F3: =Rivers!J3*'SGE density'!F3 -> 363405.34 | G3: =Rivers!K3*'SGE density'!G3 -> 428467.63 | H3: =Rivers!L3*'SGE density'!H3 -> 474947.17 | I3: =Rivers!M3*'SGE density'!I3 -> 502151.61 | J3: =Rivers!N3*'SGE density'!J3 -> 508475.67 | K3: =Rivers!O3*'SGE density'!K3 -> 486851.11 | L3: =Rivers!P3*'SGE density'!L3 -> 434868.21 | ... P3: =Rivers!T3*'SGE density'!P3 -> 291926.09 | Q3: =AVERAGE(E3:P3) -> 388625.39
A4: 2 | B4: Congo | C4: Angola | D4: South Atlantic Ocean | E4: =Rivers!I4*'SGE density'!E4 -> 85900.711 | F4: =Rivers!J4*'SGE density'!F4 -> 69585.178 | G4: =Rivers!K4*'SGE density'!G4 -> 66183.164 | H4: =Rivers!L4*'SGE density'!H4 -> 73429.229 | I4: =Rivers!M4*'SGE density'!I4 -> 82845.599 | J4: =Rivers!N4*'SGE density'!J4 -> 79387.719 | K4: =Rivers!O4*'SGE density'!K4 -> 69499.016 | L4: =Rivers!P4*'SGE density'!L4 -> 67519.373 | ... P4: =Rivers!T4*'SGE density'!P4 -> 115671.71 | Q4: =AVERAGE(E4:P4) -> 81813.434
A5: 3 | B5: Orinoco | C5: Venezuela | D5: North Atlantic Ocean | E5: =Rivers!I5*'SGE density'!E5 -> 23639.175 | F5: =Rivers!J5*'SGE density'!F5 -> 17777.144 | G5: =Rivers!K5*'SGE density'!G5 -> 14713.74 | H5: =Rivers!L5*'SGE density'!H5 -> 18336.247 | I5: =Rivers!M5*'SGE density'!I5 -> 38748.158 | J5: =Rivers!N5*'SGE density'!J5 -> 65338.267 | K5: =Rivers!O5*'SGE density'!K5 -> 100192.68 | L5: =Rivers!P5*'SGE density'!L5 -> 116870.6 | ... P5: =Rivers!T5*'SGE density'!P5 -> 45409.623 | Q5: =AVERAGE(E5:P5) -> 60509.098
A6: 4 | B6: Changjiang | C6: China | D6: North Pacific Ocean | E6: =Rivers!I6*'SGE density'!E6 -> 16632.448 | F6: =Rivers!J6*'SGE density'!F6 -> 19206.846 | G6: =Rivers!K6*'SGE density'!G6 -> 27525.311 | H6: =Rivers!L6*'SGE density'!H6 -> 39410.312 | I6: =Rivers!M6*'SGE density'!I6 -> 58635.217 | J6: =Rivers!N6*'SGE density'!J6 -> 72129.519 | K6: =Rivers!O6*'SGE density'!K6 -> 84440.73 | L6: =Rivers!P6*'SGE density'!L6 -> 87221.042 | ... P6: =Rivers!T6*'SGE density'!P6 -> 23643.325 | Q6: =AVERAGE(E6:P6) -> 50730.046
A7: 5 | B7: Brahmaputra | C7: Bangladesh | D7: Indian Ocean | E7: =Rivers!I7*'SGE density'!E7 -> 10164.174 | F7: =Rivers!J7*'SGE density'!F7 -> 8019.406 | G7: =Rivers!K7*'SGE density'!G7 -> 7544.4906 | H7: =Rivers!L7*'SGE density'!H7 -> 10827.828 | I7: =Rivers!M7*'SGE density'!I7 -> 19077.91 | J7: =Rivers!N7*'SGE density'!J7 -> 36245.109 | K7: =Rivers!O7*'SGE density'!K7 -> 60612.325 | L7: =Rivers!P7*'SGE density'!L7 -> 81553.615 | ... P7: =Rivers!T7*'SGE density'!P7 -> 17832.586 | Q7: =AVERAGE(E7:P7) -> 36139.579
A8: 6 | B8: Mississippi | C8: United States | D8: North Atlantic Ocean | E8: =Rivers!I8*'SGE density'!E8 -> 35019.848 | F8: =Rivers!J8*'SGE density'!F8 -> 39168.955 | G8: =Rivers!K8*'SGE density'!G8 -> 44163.525 | H8: =Rivers!L8*'SGE density'!H8 -> 50981.296 | I8: =Rivers!M8*'SGE density'!I8 -> 49600.091 | J8: =Rivers!N8*'SGE density'!J8 -> 36556.725 | K8: =Rivers!O8*'SGE density'!K8 -> 28041.071 | L8: =Rivers!P8*'SGE density'!L8 -> 19089.002 | ... P8: =Rivers!T8*'SGE density'!P8 -> 30153.578 | Q8: =AVERAGE(E8:P8) -> 32509.39
A9: 7 | B9: Yenisey | C9: Russia | D9: Arctic Ocean | E9: =Rivers!I9*'SGE density'!E9 -> 13478.356 | F9: =Rivers!J9*'SGE density'!F9 -> 12042.936 | G9: =Rivers!K9*'SGE density'!G9 -> 12206.643 | H9: =Rivers!L9*'SGE density'!H9 -> 12016.368 | I9: =Rivers!M9*'SGE density'!I9 -> 52024.217 | J9: =Rivers!N9*'SGE density'!J9 -> 131080.33 | K9: =Rivers!O9*'SGE density'!K9 -> 51311.622 | L9: =Rivers!P9*'SGE density'!L9 -> 33766.012 | ... P9: =Rivers!T9*'SGE density'!P9 -> 11431.746 | Q9: =AVERAGE(E9:P9) -> 33670.668
A10: 8 | B10: Parana | C10: Argentina | D10: South Atlantic Ocean | E10: =Rivers!I10*'SGE density'!E10 -> 29364.91 | F10: =Rivers!J10*'SGE density'!F10 -> 33110.312 | G10: =Rivers!K10*'SGE density'!G10 -> 34913.67 | H10: =Rivers!L10*'SGE density'!H10 -> 33090.401 | I10: =Rivers!M10*'SGE density'!I10 -> 33123.927 | J10: =Rivers!N10*'SGE density'!J10 -> 33576.469 | K10: =Rivers!O10*'SGE density'!K10 -> 33389.753 | L10: =Rivers!P10*'SGE density'!L10 -> 29282.329 | ... P10: =Rivers!T10*'SGE density'!P10 -> 28486.467 | Q10: =AVERAGE(E10:P10) -> 30845.785
A11: 9 | B11: Lena | C11: Russia | D11: Arctic Ocean | E11: =Rivers!I11*'SGE density'!E11 -> 5498.3898 | F11: =Rivers!J11*'SGE density'!F11 -> 4201.9877 | G11: =Rivers!K11*'SGE density'!G11 -> 3600.3844 | H11: =Rivers!L11*'SGE density'!H11 -> 2894.2945 | I11: =Rivers!M11*'SGE density'!I11 -> 13934.97 | J11: =Rivers!N11*'SGE density'!J11 -> 139512.22 | K11: =Rivers!O11*'SGE density'!K11 -> 73579.309 | L11: =Rivers!P11*'SGE density'!L11 -> 49802.345 | ... P11: =Rivers!T11*'SGE density'!P11 -> 5615.5964 | Q11: =AVERAGE(E11:P11) -> 31395.913
A12: 10 | B12: Mekong | C12: Vietnam | D12: South China and Easter Archipelagic Seas | E12: =Rivers!I12*'SGE density'!E12 -> 5670.4623 | F12: =Rivers!J12*'SGE density'!F12 -> 4439.9958 | G12: =Rivers!K12*'SGE density'!G12 -> 3700.5328 | H12: =Rivers!L12*'SGE density'!H12 -> 3606.5621 | I12: =Rivers!M12*'SGE density'!I12 -> 5729.3631 | J12: =Rivers!N12*'SGE density'!J12 -> 17559.106 | K12: =Rivers!O12*'SGE density'!K12 -> 31543.365 | L12: =Rivers!P12*'SGE density'!L12 -> 49729.847 | ... P12: =Rivers!T12*'SGE density'!P12 -> 8428.4736 | Q12: =AVERAGE(E12:P12) -> 18861.146
A13: 11 | B13: Tocantins | C13: Brazil | D13: South Atlantic Ocean | E13: =Rivers!I13*'SGE density'!E13 -> 24405.096 | F13: =Rivers!J13*'SGE density'!F13 -> 34403.47 | G13: =Rivers!K13*'SGE density'!G13 -> 41771.549 | H13: =Rivers!L13*'SGE density'!H13 -> 40597.071 | I13: =Rivers!M13*'SGE density'!I13 -> 31682.136 | J13: =Rivers!N13*'SGE density'!J13 -> 16004.483 | K13: =Rivers!O13*'SGE density'!K13 -> 10442.374 | L13: =Rivers!P13*'SGE density'!L13 -> 8618.2655 | ... P13: =Rivers!T13*'SGE density'!P13 -> 17657.146 | Q13: =AVERAGE(E13:P13) -> 21030.389
A14: 12 | B14: Ob | C14: Russia | D14: Arctic Ocean | E14: =Rivers!I14*'SGE density'!E14 -> 8029.4318 | F14: =Rivers!J14*'SGE density'!F14 -> 7518.7209 | G14: =Rivers!K14*'SGE density'!G14 -> 6821.8417 | H14: =Rivers!L14*'SGE density'!H14 -> 6816.9236 | I14: =Rivers!M14*'SGE density'!I14 -> 30686.214 | J14: =Rivers!N14*'SGE density'!J14 -> 62820.471 | K14: =Rivers!O14*'SGE density'!K14 -> 53140.025 | L14: =Rivers!P14*'SGE density'!L14 -> 38965.768 | ... P14: =Rivers!T14*'SGE density'!P14 -> 10033.977 | Q14: =AVERAGE(E14:P14) -> 23423.689
... A238: 236 | B238: Kymi | C238: Italy | D238: Mediterranean Region | E238: =Rivers!I238*'SGE density'!E238 -> 646.84266 | F238: =Rivers!J238*'SGE density'!F238 -> 639.44959 | G238: =Rivers!K238*'SGE density'!G238 -> 580.22479 | H238: =Rivers!L238*'SGE density'!H238 -> 645.54766 | I238: =Rivers!M238*'SGE density'!I238 -> 790.97782 | J238: =Rivers!N238*'SGE density'!J238 -> 777.55747 | K238: =Rivers!O238*'SGE density'!K238 -> 710.27382 | L238: =Rivers!P238*'SGE density'!L238 -> 661.09869 | ... P238: =Rivers!T238*'SGE density'!P238 -> 636.84396 | Q238: =AVERAGE(E238:P238) -> 661.54534
A239: 237 | B239: Sittang | C239: Myanmar | D239: Indian Ocean | E239: NaN | F239: NaN | G239: NaN | H239: NaN | I239: NaN | J239: NaN | K239: NaN | L239: NaN | M239: NaN | N239: NaN | O239: NaN | P239: NaN | Q239: NaN
A240: 238 | B240: Damodar | C240: India | D240: Indian Ocean | E240: =Rivers!I240*'SGE density'!E240 -> 54.71193 | F240: =Rivers!J240*'SGE density'!F240 -> 50.268913 | G240: =Rivers!K240*'SGE density'!G240 -> 43.157463 | H240: =Rivers!L240*'SGE density'!H240 -> 41.228279 | I240: =Rivers!M240*'SGE density'!I240 -> 73.017066 | J240: =Rivers!N240*'SGE density'!J240 -> 366.00983 | K240: =Rivers!O240*'SGE density'!K240 -> 1280.6076 | L240: =Rivers!P240*'SGE density'!L240 -> 1873.6601 | ... P240: =Rivers!T240*'SGE density'!P240 -> 78.92554 | Q240: =AVERAGE(E240:P240) -> 539.34489
A241: 239 | B241: Minho (Mino) | C241: Portugal | D241: North Atlantic Ocean | E241: =Rivers!I241*'SGE density'!E241 -> 1491.6696 | F241: =Rivers!J241*'SGE density'!F241 -> 1742.0466 | G241: =Rivers!K241*'SGE density'!G241 -> 1383.5626 | H241: =Rivers!L241*'SGE density'!H241 -> 1105.6853 | I241: =Rivers!M241*'SGE density'!I241 -> 761.67235 | J241: =Rivers!N241*'SGE density'!J241 -> 487.24378 | K241: =Rivers!O241*'SGE density'!K241 -> 286.21225 | L241: =Rivers!P241*'SGE density'!L241 -> 194.34119 | ... P241: =Rivers!T241*'SGE density'!P241 -> 1272.9915 | Q241: =AVERAGE(E241:P241) -> 834.4891
A242: 240 | B242: Nagdong (Nakdon | C242: South Korea | D242: North Pacific Ocean | E242: =Rivers!I242*'SGE density'!E242 -> 134.17246 | F242: =Rivers!J242*'SGE density'!F242 -> 176.58728 | G242: =Rivers!K242*'SGE density'!G242 -> 301.09928 | H242: =Rivers!L242*'SGE density'!H242 -> 516.00027 | I242: =Rivers!M242*'SGE density'!I242 -> 364.3771 | J242: =Rivers!N242*'SGE density'!J242 -> 391.60429 | K242: =Rivers!O242*'SGE density'!K242 -> 1563.0963 | L242: =Rivers!P242*'SGE density'!L242 -> 1042.4287 | ... P242: =Rivers!T242*'SGE density'!P242 -> 201.09724 | Q242: =AVERAGE(E242:P242) -> 541.72086
A243: 241 | B243: Patía | C243: Colombia | D243: North Pacific Ocean | E243: =Rivers!I243*'SGE density'!E243 -> 582.8378 | F243: =Rivers!J243*'SGE density'!F243 -> 544.86312 | G243: =Rivers!K243*'SGE density'!G243 -> 554.66021 | H243: =Rivers!L243*'SGE density'!H243 -> 735.69086 | I243: =Rivers!M243*'SGE density'!I243 -> 714.15436 | J243: =Rivers!N243*'SGE density'!J243 -> 496.16638 | K243: =Rivers!O243*'SGE density'!K243 -> 417.65738 | L243: =Rivers!P243*'SGE density'!L243 -> 316.85816 | ... P243: =Rivers!T243*'SGE density'!P243 -> 678.62332 | Q243: =AVERAGE(E243:P243) -> 534.57408
A244: 242 | B244: Pearl | C244: United States | D244: North Atlantic Ocean | E244: =Rivers!I244*'SGE density'!E244 -> 795.61125 | F244: =Rivers!J244*'SGE density'!F244 -> 1045.1415 | G244: =Rivers!K244*'SGE density'!G244 -> 1073.8032 | H244: =Rivers!L244*'SGE density'!H244 -> 980.25269 | I244: =Rivers!M244*'SGE density'!I244 -> 572.66434 | J244: =Rivers!N244*'SGE density'!J244 -> 286.20626 | K244: =Rivers!O244*'SGE density'!K244 -> 237.16234 | L244: =Rivers!P244*'SGE density'!L244 -> 192.61238 | ... P244: =Rivers!T244*'SGE density'!P244 -> 543.15817 | Q244: =AVERAGE(E244:P244) -> 529.02768
A245: 243 | B245: Pascagoula | C245: United States | D245: North Atlantic Ocean | E245: =Rivers!I245*'SGE density'!E245 -> 771.06477 | F245: =Rivers!J245*'SGE density'!F245 -> 952.35856 | G245: =Rivers!K245*'SGE density'!G245 -> 1048.4643 | H245: =Rivers!L245*'SGE density'!H245 -> 937.72856 | I245: =Rivers!M245*'SGE density'!I245 -> 513.15525 | J245: =Rivers!N245*'SGE density'!J245 -> 277.58236 | K245: =Rivers!O245*'SGE density'!K245 -> 275.7873 | L245: =Rivers!P245*'SGE density'!L245 -> 199.10799 | ... P245: =Rivers!T245*'SGE density'!P245 -> 573.74904 | Q245: =AVERAGE(E245:P245) -> 517.96056
A246: 244 | B246: Pee Dee | C246: United States | D246: North Atlantic Ocean | E246: =Rivers!I246*'SGE density'!E246 -> 1075.7304 | F246: =Rivers!J246*'SGE density'!F246 -> 1391.8723 | G246: =Rivers!K246*'SGE density'!G246 -> 1567.6717 | H246: =Rivers!L246*'SGE density'!H246 -> 1286.7195 | I246: =Rivers!M246*'SGE density'!I246 -> 826.81204 | J246: =Rivers!N246*'SGE density'!J246 -> 645.92463 | K246: =Rivers!O246*'SGE density'!K246 -> 598.05406 | L246: =Rivers!P246*'SGE density'!L246 -> 611.86228 | ... P246: =Rivers!T246*'SGE density'!P246 -> 771.60174 | Q246: =AVERAGE(E246:P246) -> 871.8576
A247: 245 | B247: Kem | C247: Russia | D247: Arctic Ocean | E247: =Rivers!I247*'SGE density'!E247 -> 314.52227 | F247: =Rivers!J247*'SGE density'!F247 -> 262.06034 | G247: =Rivers!K247*'SGE density'!G247 -> 210.69256 | H247: =Rivers!L247*'SGE density'!H247 -> 273.36351 | I247: =Rivers!M247*'SGE density'!I247 -> 1112.3306 | J247: =Rivers!N247*'SGE density'!J247 -> 1061.5572 | K247: =Rivers!O247*'SGE density'!K247 -> 706.07564 | L247: =Rivers!P247*'SGE density'!L247 -> 576.99566 | ... P247: =Rivers!T247*'SGE density'!P247 -> 382.44585 | Q247: =AVERAGE(E247:P247) -> 539.88486
A248: 246 | B248: Waiau (S) | C248: New Zealand | D248: South Pacific Ocean | E248: =Rivers!I248*'SGE density'!E248 -> 616.18726 | F248: =Rivers!J248*'SGE density'!F248 -> 635.59086 | G248: =Rivers!K248*'SGE density'!G248 -> 652.60191 | H248: =Rivers!L248*'SGE density'!H248 -> 647.01893 | I248: =Rivers!M248*'SGE density'!I248 -> 627.46055 | J248: =Rivers!N248*'SGE density'!J248 -> 549.81829 | K248: =Rivers!O248*'SGE density'!K248 -> 507.34912 | L248: =Rivers!P248*'SGE density'!L248 -> 485.32212 | ... P248: =Rivers!T248*'SGE density'!P248 -> 682.65666 | Q248: =AVERAGE(E248:P248) -> 615.77548
A249: 247 | B249: Ntem | C249: Cameroon | D249: North Atlantic Ocean | E249: =Rivers!I249*'SGE density'!E249 -> 231.72058 | F249: =Rivers!J249*'SGE density'!F249 -> 198.12006 | G249: =Rivers!K249*'SGE density'!G249 -> 290.00202 | H249: =Rivers!L249*'SGE density'!H249 -> 497.34297 | I249: =Rivers!M249*'SGE density'!I249 -> 617.78031 | J249: =Rivers!N249*'SGE density'!J249 -> 606.65943 | K249: =Rivers!O249*'SGE density'!K249 -> 368.64741 | L249: =Rivers!P249*'SGE density'!L249 -> 176.73836 | ... P249: =Rivers!T249*'SGE density'!P249 -> 565.35426 | Q249: =AVERAGE(E249:P249) -> 499.3806
A250: 248 | B250: Mae Klong | C250: Thailand | D250: South China and Easter Archipelagic Seas | E250: =Rivers!I250*'SGE density'!E250 -> 261.42494 | F250: =Rivers!J250*'SGE density'!F250 -> 248.82203 | G250: =Rivers!K250*'SGE density'!G250 -> 470.52301 | H250: =Rivers!L250*'SGE density'!H250 -> 715.33681 | I250: =Rivers!M250*'SGE density'!I250 -> 1191.6189 | J250: =Rivers!N250*'SGE density'!J250 -> 1173.4486 | K250: =Rivers!O250*'SGE density'!K250 -> 1003.6191 | L250: =Rivers!P250*'SGE density'!L250 -> 490.73706 | ... P250: =Rivers!T250*'SGE density'!P250 -> 183.58982 | Q250: =AVERAGE(E250:P250) -> 538.13009
A251: 249 | B251: Cagayan | C251: Philippines | D251: South China and Easter Archipelagic Seas | E251: =Rivers!I251*'SGE density'!E251 -> 423.07682 | F251: =Rivers!J251*'SGE density'!F251 -> 243.16871 | G251: =Rivers!K251*'SGE density'!G251 -> 269.14207 | H251: =Rivers!L251*'SGE density'!H251 -> 161.19535 | I251: =Rivers!M251*'SGE density'!I251 -> 191.67523 | J251: =Rivers!N251*'SGE density'!J251 -> 280.71445 | K251: =Rivers!O251*'SGE density'!K251 -> 558.39387 | L251: =Rivers!P251*'SGE density'!L251 -> 349.70362 | ... P251: =Rivers!T251*'SGE density'!P251 -> 953.19786 | Q251: =AVERAGE(E251:P251) -> 551.42757
... A457: 455 | B457: Kiiminki | C457: Finland | D457: Baltic Sea | E457: =Rivers!I457*'SGE density'!E457 -> 31.522885 | F457: =Rivers!J457*'SGE density'!F457 -> 18.756552 | G457: =Rivers!K457*'SGE density'!G457 -> 15.580348 | H457: =Rivers!L457*'SGE density'!H457 -> 103.92985 | I457: =Rivers!M457*'SGE density'!I457 -> 289.06116 | J457: =Rivers!N457*'SGE density'!J457 -> 120.76104 | K457: =Rivers!O457*'SGE density'!K457 -> 53.270484 | L457: =Rivers!P457*'SGE density'!L457 -> 51.054318 | ... P457: =Rivers!T457*'SGE density'!P457 -> 56.266876 | Q457: =AVERAGE(E457:P457) -> 80.347117
A458: 456 | B458: Tuxpan | C458: Mexico | D458: North Atlantic Ocean | E458: =Rivers!I458*'SGE density'!E458 -> 46.389368 | F458: =Rivers!J458*'SGE density'!F458 -> 38.77727 | G458: =Rivers!K458*'SGE density'!G458 -> 36.303461 | H458: =Rivers!L458*'SGE density'!H458 -> 30.467883 | I458: =Rivers!M458*'SGE density'!I458 -> 47.352276 | J458: =Rivers!N458*'SGE density'!J458 -> 137.68125 | K458: =Rivers!O458*'SGE density'!K458 -> 273.53437 | L458: =Rivers!P458*'SGE density'!L458 -> 104.32862 | M458: NaN | N458: =Rivers!R458*'SGE density'!N458 -> 126.80478 | O458: =Rivers!S458*'SGE density'!O458 -> 187.57901 | P458: =Rivers!T458*'SGE density'!P458 -> 118.03139 | Q458: =AVERAGE(E458:P458) -> 104.29543
A459: 457 | B459: Var | C459: France | D459: Mediterranean Region | E459: =Rivers!I459*'SGE density'!E459 -> 72.023679 | F459: =Rivers!J459*'SGE density'!F459 -> 89.605621 | G459: =Rivers!K459*'SGE density'!G459 -> 110.47023 | H459: =Rivers!L459*'SGE density'!H459 -> 95.507415 | I459: =Rivers!M459*'SGE density'!I459 -> 155.38056 | J459: =Rivers!N459*'SGE density'!J459 -> 170.38236 | K459: =Rivers!O459*'SGE density'!K459 -> 87.195535 | L459: =Rivers!P459*'SGE density'!L459 -> 51.391578 | ... P459: =Rivers!T459*'SGE density'!P459 -> 48.034077 | Q459: =AVERAGE(E459:P459) -> 92.037212
A460: 458 | B460: Yeong San | C460: South Korea | D460: North Pacific Ocean | E460: =Rivers!I460*'SGE density'!E460 -> 32.823347 | F460: =Rivers!J460*'SGE density'!F460 -> 61.915313 | G460: =Rivers!K460*'SGE density'!G460 -> 47.741484 | H460: =Rivers!L460*'SGE density'!H460 -> 100.74857 | I460: =Rivers!M460*'SGE density'!I460 -> 61.580343 | J460: =Rivers!N460*'SGE density'!J460 -> 174.2171 | K460: =Rivers!O460*'SGE density'!K460 -> 97.079865 | L460: =Rivers!P460*'SGE density'!L460 -> 142.39317 | ... P460: =Rivers!T460*'SGE density'!P460 -> 36.590901 | Q460: =AVERAGE(E460:P460) -> 78.49735
A461: 459 | B461: Coco | C461: Honduras | D461: North Pacific Ocean | E461: =Rivers!I461*'SGE density'!E461 -> 20.288437 | F461: =Rivers!J461*'SGE density'!F461 -> 13.012794 | G461: =Rivers!K461*'SGE density'!G461 -> 10.071784 | H461: =Rivers!L461*'SGE density'!H461 -> 12.152744 | I461: =Rivers!M461*'SGE density'!I461 -> 89.824313 | J461: =Rivers!N461*'SGE density'!J461 -> 80.480113 | K461: =Rivers!O461*'SGE density'!K461 -> 77.833175 | L461: =Rivers!P461*'SGE density'!L461 -> 96.905606 | ... P461: =Rivers!T461*'SGE density'!P461 -> 27.038946 | Q461: =AVERAGE(E461:P461) -> 65.661666
A462: 460 | B462: Palyavaam | C462: Russia | D462: Arctic Ocean | E462: =Rivers!I462*'SGE density'!E462 -> 0.0019150575 | F462: =Rivers!J462*'SGE density'!F462 -> 0.0016947431 | G462: =Rivers!K462*'SGE density'!G462 -> 0.0016831957 | H462: =Rivers!L462*'SGE density'!H462 -> 0.0017191416 | I462: =Rivers!M462*'SGE density'!I462 -> 22.377409 | J462: =Rivers!N462*'SGE density'!J462 -> 332.76003 | K462: =Rivers!O462*'SGE density'!K462 -> 211.48079 | L462: =Rivers!P462*'SGE density'!L462 -> 172.95463 | ... P462: =Rivers!T462*'SGE density'!P462 -> 0.19812732 | Q462: =AVERAGE(E462:P462) -> 70.435083
A463: 461 | B463: Kikuchi | C463: Japan | D463: North Pacific Ocean | E463: =Rivers!I463*'SGE density'!E463 -> 31.395953 | F463: =Rivers!J463*'SGE density'!F463 -> 31.522359 | G463: =Rivers!K463*'SGE density'!G463 -> 38.154676 | H463: =Rivers!L463*'SGE density'!H463 -> 51.419009 | I463: =Rivers!M463*'SGE density'!I463 -> 73.736824 | J463: =Rivers!N463*'SGE density'!J463 -> 129.42329 | K463: =Rivers!O463*'SGE density'!K463 -> 233.8663 | L463: =Rivers!P463*'SGE density'!L463 -> 107.89402 | ... P463: =Rivers!T463*'SGE density'!P463 -> 34.415641 | Q463: =AVERAGE(E463:P463) -> 75.303747
A464: 462 | B464: Candelaria | C464: Mexico | D464: North Atlantic Ocean | E464: =Rivers!I464*'SGE density'!E464 -> 63.127872 | F464: =Rivers!J464*'SGE density'!F464 -> 43.275131 | G464: =Rivers!K464*'SGE density'!G464 -> 42.04108 | H464: =Rivers!L464*'SGE density'!H464 -> 35.795288 | I464: =Rivers!M464*'SGE density'!I464 -> 32.705832 | J464: =Rivers!N464*'SGE density'!J464 -> 43.230909 | K464: =Rivers!O464*'SGE density'!K464 -> 73.246156 | L464: =Rivers!P464*'SGE density'!L464 -> 72.287439 | ... P464: =Rivers!T464*'SGE density'!P464 -> 133.67187 | Q464: =AVERAGE(E464:P464) -> 88.092461
A465: 463 | B465: Almas [das] (Je | C465: Brazil | D465: South Atlantic Ocean | E465: =Rivers!I465*'SGE density'!E465 -> 81.929795 | F465: =Rivers!J465*'SGE density'!F465 -> 81.390892 | G465: =Rivers!K465*'SGE density'!G465 -> 88.244317 | H465: =Rivers!L465*'SGE density'!H465 -> 111.37074 | I465: =Rivers!M465*'SGE density'!I465 -> 96.644183 | J465: =Rivers!N465*'SGE density'!J465 -> 104.73568 | K465: =Rivers!O465*'SGE density'!K465 -> 120.76523 | L465: =Rivers!P465*'SGE density'!L465 -> 117.27333 | ... P465: =Rivers!T465*'SGE density'!P465 -> 97.92638 | Q465: =AVERAGE(E465:P465) -> 97.683033
A466: 464 | B466: Sinaloa | C466: Mexico | D466: North Pacific Ocean | E466: =Rivers!I466*'SGE density'!E466 -> 95.824172 | F466: =Rivers!J466*'SGE density'!F466 -> 47.021324 | G466: =Rivers!K466*'SGE density'!G466 -> 24.3308 | H466: =Rivers!L466*'SGE density'!H466 -> 9.844993 | I466: =Rivers!M466*'SGE density'!I466 -> 8.8116526 | J466: =Rivers!N466*'SGE density'!J466 -> 23.68678 | K466: =Rivers!O466*'SGE density'!K466 -> 158.53714 | L466: =Rivers!P466*'SGE density'!L466 -> 252.3288 | ... P466: =Rivers!T466*'SGE density'!P466 -> 70.429162 | Q466: =AVERAGE(E466:P466) -> 85.240965
A467: 465 | B467: Trang | C467: Thailand | D467: South China and Easter Archipelagic Seas | E467: =Rivers!I467*'SGE density'!E467 -> 87.51622 | F467: =Rivers!J467*'SGE density'!F467 -> 22.901908 | G467: =Rivers!K467*'SGE density'!G467 -> 13.79119 | H467: =Rivers!L467*'SGE density'!H467 -> 12.959441 | I467: =Rivers!M467*'SGE density'!I467 -> 29.537393 | J467: =Rivers!N467*'SGE density'!J467 -> 39.040009 | K467: =Rivers!O467*'SGE density'!K467 -> 67.032188 | L467: =Rivers!P467*'SGE density'!L467 -> 63.151377 | ... P467: =Rivers!T467*'SGE density'!P467 -> 145.69066 | Q467: =AVERAGE(E467:P467) -> 74.026139
A468: 466 | B468: Midori | C468: Japan | D468: North Pacific Ocean | E468: =Rivers!I468*'SGE density'!E468 -> 27.172808 | F468: =Rivers!J468*'SGE density'!F468 -> 28.363585 | G468: =Rivers!K468*'SGE density'!G468 -> 33.620731 | H468: =Rivers!L468*'SGE density'!H468 -> 46.20784 | I468: =Rivers!M468*'SGE density'!I468 -> 47.071578 | J468: =Rivers!N468*'SGE density'!J468 -> 154.67647 | K468: =Rivers!O468*'SGE density'!K468 -> 269.52592 | L468: =Rivers!P468*'SGE density'!L468 -> 134.47089 | ... P468: =Rivers!T468*'SGE density'!P468 -> 28.875056 | Q468: =AVERAGE(E468:P468) -> 76.808277
...

Sheet Extractable SGE potential
A1: River ID | B1: River name | C1: Country | D1: Ocean Basin | E1: Extractable SGE Potential (MW) (see the associated research paper for details on the methodology)
E2: January | F2: February | G2: March | H2: April | I2: May | J2: June | K2: July | L2: August | M2: September | N2: October | O2: November | P2: December | Q2: Average
A3: 1 | B3: Amazon | C3: Brazil | D3: North Atlantic Ocean | E3: 99815.383 | F3: 99593.234 | G3: 99538.156 | H3: 98559.109 | I3: 101014.23 | J3: 109174.48 | K3: 115449.53 | L3: 120146.66 | M3: 121303.78 | N3: 121493.89 | O3: 121368.98 | P3: 120282.73 | Q3: =AVERAGE(E3:P3) -> 110645.01
A4: 2 | B4: Congo | C4: Angola | D4: South Atlantic Ocean | E4: 32996.867 | F4: 33764.82 | G4: 35225.668 | H4: 36603.688 | I4: 39544.902 | J4: 40607.297 | K4: 40962.949 | L4: 40386.656 | M4: 38791.559 | N4: 37928.668 | O4: 38563.82 | P4: 37971.219 | Q4: =AVERAGE(E4:P4) -> 37779.009
A5: 3 | B5: Orinoco | C5: Venezuela | D5: North Atlantic Ocean | E5: 6881.4326 | F5: 0 | G5: 0 | H5: 0 | I5: 20256.771 | J5: 40958 | K5: 42385.34 | L5: 40201.355 | M5: 43472.047 | N5: 47145.656 | O5: 47209.867 | P5: 25633.611 | Q5: =AVERAGE(E5:P5) -> 26178.673
A6: 4 | B6: Changjiang | C6: China | D6: North Pacific Ocean | E6: 2311.8464 | F6: 2351.0776 | G6: 2352.6182 | H6: 2406.738 | I6: 2504.0374 | J6: 2542.5586 | K6: 2583.5806 | L6: 2760.3259 | M6: 2584.7288 | N6: 2533.9597 | O6: 2491.9631 | P6: 2415.2458 | Q6: =AVERAGE(E6:P6) -> 2486.5567
A7: 5 | B7: Brahmaputra | C7: Bangladesh | D7: Indian Ocean | E7: 139.37646 | F7: 0 | G7: 0 | H7: 0 | I7: 7577.0562 | J7: 24994.061 | K7: 24041.824 | L7: 24238.041 | M7: 24126.477 | N7: 24277.205 | O7: 23779.91 | P7: 7482.1543 | Q7: =AVERAGE(E7:P7) -> 13388.009
A8: 6 | B8: Mississippi | C8: United States | D8: North Atlantic Ocean | E8: 6538.7012 | F8: 6380.5532 | G8: 6050.8594 | H8: 6455.0313 | I8: 6750.7861 | J8: 6225.7476 | K8: 6274.9326 | L8: 6190.2036 | M8: 6887.8174 | N8: 7093.6284 | O8: 7044.7769 | P8: 6915.8105 | Q8: =AVERAGE(E8:P8) -> 6567.404
A9: 7 | B9: Yenisey | C9: Russia | D9: Arctic Ocean | E9: 1835.7026 | F9: 1631.0707 | G9: 1693.5371 | H9: 1643.5396 | I9: 1686.5273 | J9: 1556.0891 | K9: 1847.9384 | L9: 1817.5782 | M9: 1810.8607 | N9: 1795.5598 | O9: 1635.3817 | P9: 1601.7213 | Q9: =AVERAGE(E9:P9) -> 1712.9589
A10: 8 | B10: Parana | C10: Argentina | D10: South Atlantic Ocean | E10: 15768.696 | F10: 16121.1 | G10: 16117.853 | H10: 15133.57 | I10: 16023.813 | J10: 16951.848 | K10: 17292.889 | L10: 17076.723 | M10: 17108.063 | N10: 16915.365 | O10: 15529.19 | P10: 16572.5 | Q10: =AVERAGE(E10:P10) -> 16384.301
A11: 9 | B11: Lena | C11: Russia | D11: Arctic Ocean | E11: 0 | F11: 0 | G11: 0 | H11: 0 | I11: 4288.5234 | J11: 32062.598 | K11: 31529.189 | L11: 30884.609 | M11: 30550.504 | N11: 17503.867 | O11: 0 | P11: 0 | Q11: =AVERAGE(E11:P11) -> 12234.941
A12: 10 | B12: Mekong | C12: Vietnam | D12: South China and Easter Archipelagic Seas | E12: 0 | F12: 0 | G12: 0 | H12: 0 | I12: 0 | J12: 11498.063 | K12: 10627.569 | L12: 10631.779 | M12: 10759.588 | N12: 10713.424 | O12: 9832.3086 | P12: 2443.9905 | Q12: =AVERAGE(E12:P12) -> 5542.2268
A13: 11 | B13: Tocantins | C13: Brazil | D13: South Atlantic Ocean | E13: 391.77579 | F13: 389.87375 | G13: 396.31989 | H13: 385.62354 | I13: 453.24243 | J13: 465.81421 | K13: 471.47906 | L13: 473.47928 | M13: 473.24661 | N13: 471.67462 | O13: 472.34973 | P13: 471.04791 | Q13: =AVERAGE(E13:P13) -> 442.9939
A14: 12 | B14: Ob | C14: Russia | D14: Arctic Ocean | E14: 1684.0786 | F14: 532.42981 | G14: 0 | H14: 0 | I14: 3188.73 | J14: 3142.3879 | K14: 2993.2913 | L14: 2972.1511 | M14: 3017.0491 | N14: 3035.3091 | O14: 3015.6479 | P14: 3011.6497 | Q14: =AVERAGE(E14:P14) -> 2216.0604
... A1080: 1078 | B1080: Rio Caroni | C1080: Trinidad and Tobago | D1080: North Atlantic Ocean | E1080: 2.5918353 | F1080: 0 | G1080: 0 | H1080: 0.17873582 | I1080: 3.4073365 | J1080: 3.2259665 | K1080: 3.0355365 | L1080: 3.0100055 | M1080: 2.9516175 | N1080: 3.0883319 | O1080: 3.2965157 | P1080: 3.4582644 | Q1080: =AVERAGE(E1080:P1080) -> 2.3536788

Sheet Summary_Basin
A1: Ocean Basin | B1: Extractable SGE Potential by Ocean Basin (MW) (see the associated research paper for details on the methodology)
B2: January | C2: February | D2: March | E2: April | F2: May | G2: June | H2: July | I2: August | J2: September | K2: October | L2: November | M2: December | N2: Average
